Traceback (most recent call last):
  File "1d_regression.py", line 12, in <module>
    from utils.utils import variational_solution_vs_neural_network, setup
  File "/home/ata36/generalisation-claims/utils/utils.py", line 8, in <module>
    from datasets.dataset import generate_sine_interpolation, generate_sine_extrapolation_dataset, \
ImportError: cannot import name 'generate_sine_extrapolation_dataset'
Traceback (most recent call last):
  File "1d_regression.py", line 12, in <module>
    from utils.utils import variational_solution_vs_neural_network, setup
  File "/home/ata36/generalisation-claims/utils/utils.py", line 8, in <module>
    from datasets.dataset import generate_sine_interpolation, generate_sine_extrapolation_dataset, \
ImportError: cannot import name 'generate_sine_extrapolation_dataset'
Traceback (most recent call last):
  File "1d_regression.py", line 12, in <module>
    from utils.utils import variational_solution_vs_neural_network, setup
  File "/home/ata36/generalisation-claims/utils/utils.py", line 8, in <module>
    from datasets.dataset import generate_sine_interpolation, generate_sine_extrapolation_dataset, \
ImportError: cannot import name 'generate_sine_extrapolation_dataset'
Traceback (most recent call last):
  File "1d_regression.py", line 12, in <module>
    from utils.utils import variational_solution_vs_neural_network, setup
  File "/home/ata36/generalisation-claims/utils/utils.py", line 8, in <module>
    from datasets.dataset import generate_sine_interpolation, generate_sine_extrapolation_dataset, \
ImportError: cannot import name 'generate_sine_extrapolation_dataset'
Traceback (most recent call last):
  File "1d_regression.py", line 12, in <module>
    from utils.utils import variational_solution_vs_neural_network, setup
  File "/home/ata36/generalisation-claims/utils/utils.py", line 8, in <module>
    from datasets.dataset import generate_sine_interpolation, generate_sine_extrapolation_dataset, \
ImportError: cannot import name 'generate_sine_extrapolation_dataset'
Traceback (most recent call last):
  File "1d_regression.py", line 12, in <module>
    from utils.utils import variational_solution_vs_neural_network, setup
  File "/home/ata36/generalisation-claims/utils/utils.py", line 8, in <module>
    from datasets.dataset import generate_sine_interpolation, generate_sine_extrapolation_dataset, \
ImportError: cannot import name 'generate_sine_extrapolation_dataset'
Traceback (most recent call last):
  File "1d_regression.py", line 12, in <module>
    from utils.utils import variational_solution_vs_neural_network, setup
  File "/home/ata36/generalisation-claims/utils/utils.py", line 8, in <module>
    from datasets.dataset import generate_sine_interpolation, generate_sine_extrapolation_dataset, \
ImportError: cannot import name 'generate_sine_extrapolation_dataset'
Traceback (most recent call last):
  File "1d_regression.py", line 12, in <module>
    from utils.utils import variational_solution_vs_neural_network, setup
  File "/home/ata36/generalisation-claims/utils/utils.py", line 8, in <module>
    from datasets.dataset import generate_sine_interpolation, generate_sine_extrapolation_dataset, \
ImportError: cannot import name 'generate_sine_extrapolation_dataset'
Traceback (most recent call last):
  File "1d_regression.py", line 12, in <module>
    from utils.utils import variational_solution_vs_neural_network, setup
  File "/home/ata36/generalisation-claims/utils/utils.py", line 8, in <module>
    from datasets.dataset import generate_sine_interpolation, generate_sine_extrapolation_dataset, \
ImportError: cannot import name 'generate_sine_extrapolation_dataset'
Traceback (most recent call last):
  File "1d_regression.py", line 12, in <module>
    from utils.utils import variational_solution_vs_neural_network, setup
  File "/home/ata36/generalisation-claims/utils/utils.py", line 8, in <module>
    from datasets.dataset import generate_sine_interpolation, generate_sine_extrapolation_dataset, \
ImportError: cannot import name 'generate_sine_extrapolation_dataset'
Traceback (most recent call last):
  File "1d_regression.py", line 12, in <module>
    from utils.utils import variational_solution_vs_neural_network, setup
  File "/home/ata36/generalisation-claims/utils/utils.py", line 8, in <module>
    from datasets.dataset import generate_sine_interpolation, generate_sine_extrapolation_dataset, \
ImportError: cannot import name 'generate_sine_extrapolation_dataset'
Traceback (most recent call last):
  File "1d_regression.py", line 12, in <module>
    from utils.utils import variational_solution_vs_neural_network, setup
  File "/home/ata36/generalisation-claims/utils/utils.py", line 8, in <module>
    from datasets.dataset import generate_sine_interpolation, generate_sine_extrapolation_dataset, \
ImportError: cannot import name 'generate_sine_extrapolation_dataset'
Traceback (most recent call last):
  File "1d_regression.py", line 12, in <module>
    from utils.utils import variational_solution_vs_neural_network, setup
  File "/home/ata36/generalisation-claims/utils/utils.py", line 8, in <module>
    from datasets.dataset import generate_sine_interpolation, generate_sine_extrapolation_dataset, \
ImportError: cannot import name 'generate_sine_extrapolation_dataset'
Traceback (most recent call last):
  File "1d_regression.py", line 12, in <module>
    from utils.utils import variational_solution_vs_neural_network, setup
  File "/home/ata36/generalisation-claims/utils/utils.py", line 8, in <module>
    from datasets.dataset import generate_sine_interpolation, generate_sine_extrapolation_dataset, \
ImportError: cannot import name 'generate_sine_extrapolation_dataset'
Traceback (most recent call last):
  File "1d_regression.py", line 12, in <module>
    from utils.utils import variational_solution_vs_neural_network, setup
  File "/home/ata36/generalisation-claims/utils/utils.py", line 8, in <module>
    from datasets.dataset import generate_sine_interpolation, generate_sine_extrapolation_dataset, \
ImportError: cannot import name 'generate_sine_extrapolation_dataset'
